Workbook

Sheet Raw_Data
A1: Country Name | B1: Country Code | C1: Series Name | D1: Series Code | E1: 2000 | F1: 2001 | G1: 2002 | H1: 2003 | I1: 2004 | J1: 2005 | K1: 2006 | L1: 2007 | M1: 2008 | N1: 2009 | O1: 2010 | P1: 2011 | Q1: 2012 | R1: 2013 | S1: 2014 | T1: 2015 | U1: 2016 | V1: 2017 | W1: 2018 | X1: 2019 | Y1: 2020 | Z1: 2021 | AA1: 2022 | AB1: 2023 | AC1: 2024
A2: Philippines | B2: PHL | C2: Fixed broadband subscriptions | D2: IT.NET.BBND | F2: 10000 | G2: 21000 | H2: 55000 | I2: 89000 | J2: 123000 | K2: 265030 | L2: 496151 | M2: 1045716 | N2: 1722407 | P2: 1791000 | Q2: 2146600 | R2: 2572800 | S2: 2900000 | T2: 2900000 | U2: 2985452 | V2: 3399291 | W2: 3788489 | X2: 6312883 | Y2: 7936574 | Z2: 9623734 | AA2: 8706266 | AB2: 7513090 | AC2: 8270002
A3: Philippines | B3: PHL | C3: Fixed broadband subscriptions (per 100 people) | D3: IT.NET.BBND.P2 | F3: 0.012284788 | G3: 0.025280223 | H3: 0.064910668 | I3: 0.10301581 | J3: 0.13974738 | K3: 0.29609318 | L3: 0.54477079 | M3: 1.1280757 | N3: 1.8248882 | P3: 1.8229265 | Q3: 2.1428391 | R3: 2.5204666 | S3: 2.7947193 | T3: 2.7536963 | U3: 2.7970505 | V3: 3.1440073 | W3: 3.4609045 | X3: 5.697307 | Y3: 7.0810889 | Z3: 8.5089772 | AA3: 7.6394653 | AB3: 6.5393086 | AC3: 7.138933
A4: Philippines | B4: PHL | C4: Fixed telephone subscriptions | D4: IT.MLT.MAIN | E4: 3061387 | F4: 3315091 | G4: 3310933 | H4: 3340000 | I4: 3437491 | J4: 3367252 | K4: 3633188 | L4: 3940082 | M4: 4076140 | N4: 4100000 | O4: 3335398 | P4: 3555951 | Q4: 3493164 | R4: 3148835 | S4: 3093236 | T4: 3223787 | U4: 3781962 | V4: 4163282 | W4: 4132435 | X4: 4255808 | Y4: 4731196 | Z4: 4672737 | AA4: 4799424 | AB4: 4627105 | AC4: 4422371
A5: Philippines | B5: PHL | C5: Fixed telephone subscriptions (per 100 people) | D5: IT.MLT.MAIN.P2 | E5: 3.8447369 | F5: 4.0725189 | G5: 3.9857678 | H5: 3.9418478 | I5: 3.9788306 | J5: 3.8257288 | K5: 4.0590204 | L5: 4.3261862 | M5: 4.3971735 | N5: 4.3439451 | O5: 3.4622146 | P5: 3.6193396 | Q5: 3.4870438 | R5: 3.0847845 | S5: 2.9809401 | T5: 3.0611484 | U5: 3.5432956 | V5: 3.8506232 | W5: 3.77511 | X5: 3.8408196 | Y5: 4.2212193 | Z5: 4.1314746 | AA5: 4.2113385 | AB5: 4.0273799 | AC5: 3.8175336
A6: Philippines | B6: PHL | C6: ICT goods exports (% of total goods exports) | D6: TX.VAL.ICTG.ZS.UN | E6: 36.85 | F6: 38.62 | G6: 38.02 | H6: 36.58 | I6: 34.75 | J6: 44.6 | K6: 44.88 | L6: 31.08 | M6: 27.86 | N6: 33.33 | O6: 22.46 | P6: 18.03 | Q6: 25.89 | R6: 23.58 | S6: 31.22 | T6: 38.85 | U6: 39.77 | V6: 34.04 | W6: 37 | X6: 47.76 | Y6: 49.47 | Z6: 47.3 | AA6: 49.77 | AB6: 47.4 | AC6: 43.57
A7: Philippines | B7: PHL | C7: ICT goods imports (% total goods imports) | D7: TM.VAL.ICTG.ZS.UN | E7: 37.74 | F7: 42.32 | G7: 51.27 | H7: 48.56 | I7: 48.06 | J7: 45.62 | K7: 43.91 | L7: 42.41 | M7: 33.34 | N7: 32.88 | O7: 31.18 | P7: 13.03 | Q7: 24.64 | R7: 22.81 | S7: 20.62 | T7: 26.75 | U7: 23.6 | V7: 19.32 | W7: 21.73 | X7: 20.26 | Y7: 23.66 | Z7: 21.13 | AA7: 18.77 | AB7: 16.44 | AC7: 16.44
A8: Philippines | B8: PHL | C8: ICT service exports (% of service exports, BoP) | D8: BX.GSR.CCIS.ZS | E8: 4.5915643 | F8: 7.1094861 | G8: 7.4439462 | H8: 8.1362513 | I8: 7.711701 | J8: 7.588732 | K8: 9.1575593 | L8: 10.109936 | M8: 12.2869 | N8: 13.469192 | O8: 12.573826 | P8: 14.665699 | Q8: 14.693212 | R8: 14.29545 | S8: 13.618079 | T8: 11.907593 | U8: 17.604271 | V8: 16.187671 | W8: 15.469859 | X8: 14.778028 | Y8: 18.633839 | Z8: 18.76552 | AA8: 16.227603 | AB8: 14.68609 | AC8: 15.956608
A9: Philippines | B9: PHL | C9: ICT service exports (BoP, current US$) | D9: BX.GSR.CCIS.CD | E9: 258000000 | F9: 350000000 | G9: 415000000 | H9: 461000000 | I9: 520000000 | J9: 6.5345616e+08 | K9: 1.0132131e+09 | L9: 1.3650147e+09 | M9: 1.6040289e+09 | N9: 1.8970185e+09 | O9: 2.2359079e+09 | P9: 2.7686203e+09 | Q9: 3.0031752e+09 | R9: 3.3358655e+09 | S9: 3.4723502e+09 | T9: 3.4609475e+09 | U9: 5.4931673e+09 | V9: 5.6384325e+09 | W9: 5.9399747e+09 | X9: 6.0980083e+09 | Y9: 5.9296975e+09 | Z9: 6.2995866e+09 | AA9: 6.6730969e+09 | AB9: 7.0980575e+09 | AC9: 8.0854292e+09
A10: Philippines | B10: PHL | C10: Individuals using the Internet (% of population) | D10: IT.NET.USER.ZS | E10: 1.9822532 | F10: 2.5240057 | G10: 4.3322757 | H10: 4.8576723 | I10: 5.2436285 | J10: 5.3976002 | K10: 5.7405863 | L10: 5.97 | M10: 6.22 | N10: 9 | O10: 25 | P10: 29 | Q10: 30.799999 | R10: 32.700001 | S10: 34.700001 | T10: 36.900002 | U10: 39.200001 | V10: 41.599998 | W10: 44.099998 | X10: 43.026612 | Y10: 53.7649 | Z10: 66.907799 | AA10: 75.211144 | AB10: 77.866997 | AC10: 67.263009
A11: Philippines | B11: PHL | C11: Individuals using the Internet, female (% of female population) | D11: IT.NET.USER.FE.ZS | AA11: 75.1505 | AC11: 69.9401
A12: Philippines | B12: PHL | C12: Individuals using the Internet, male (% of male population) | D12: IT.NET.USER.MA.ZS | AA12: 75.2716 | AC12: 64.6093
A13: Philippines | B13: PHL | C13: Mobile cellular subscriptions | D13: IT.CEL.SETS | E13: 6454359 | F13: 12159163 | G13: 15383001 | H13: 22509560 | I13: 32935875 | J13: 34778995 | K13: 42868911 | L13: 57344815 | M13: 68117167 | N13: 75586646 | O13: 83150138 | P13: 94189795 | Q13: 101978345 | R13: 102823569 | S13: 111326045 | T13: 117838074 | U13: 120096895 | V13: 119971922 | W13: 134599017 | X13: 167322432 | Y13: 149579406 | Z13: 163345244 | AA13: 168016400 | AB13: 134739253 | AC13: 133566303
A14: Philippines | B14: PHL | C14: Mobile cellular subscriptions (per 100 people) | D14: IT.CEL.SETS.P2 | E14: 8.105905 | F14: 14.937274 | G14: 18.518366 | H14: 26.565647 | I14: 38.122651 | J14: 39.514418 | K14: 47.893416 | L14: 62.964259 | M14: 73.482019 | N14: 80.083961 | O14: 86.311625 | P14: 95.868828 | Q14: 101.79967 | R14: 100.73203 | S14: 107.2845 | T14: 111.8932 | U14: 112.518 | V14: 110.96214 | W14: 122.96046 | X14: 151.00664 | Y14: 133.45621 | Z14: 144.42429 | AA14: 147.42893 | AB14: 117.27552 | AC14: 115.29875
A15: Philippines | B15: PHL | C15: Secure Internet servers | D15: IT.NET.SECR | O15: 474 | P15: 674 | Q15: 1146 | R15: 1233 | S15: 1619 | T15: 2139 | U15: 4202 | V15: 9239 | W15: 9903 | X15: 12035 | Y15: 12444 | Z15: 15116 | AA15: 11418 | AB15: 35099 | AC15: 15240
A16: Philippines | B16: PHL | C16: Secure Internet servers (per 1 million people) | D16: IT.NET.SECR.P6 | O16: 4.9202216 | P16: 6.8601477 | Q16: 11.439922 | R16: 12.079195 | S16: 15.602243 | T16: 20.310884 | U16: 39.368264 | V16: 85.451593 | W16: 90.467035 | X16: 108.61454 | Y16: 111.02659 | Z16: 133.65051 | AA16: 100.18924 | AB16: 305.49773 | AC16: 131.55661

Sheet Data_Description
A1: Code | B1: License Type | C1: Indicator Name | D1: Long definition | E1: Source | F1: Topic | G1: Dataset | H1: Unit of measure | I1: Periodicity | J1: Reference period | K1: Aggregation method | L1: Statistical concept and methodology | M1: Development relevance | N1: Limitations and exceptions | O1: Other notes | P1: License URL
A2: IT.NET.BBND | B2: CC BY-4.0 | C2: Fixed broadband subscriptions | D2: Fixed broadband subscriptions refers to fixed subscriptions to high-speed access to the public Internet (a TCP/IP connection), at downstream speeds equal to, or greater than, 256 kbit/s. This includes cable modem, DSL, fiber-to-the-home/building, other fixed (wired)-broadband subscriptions, satellite broadband and terrestrial fixed wireless broadband. This total is measured irrespective of the method of payment. It excludes subscriptions that have access to data communications (including the Internet) via mobile-cellular networks. It should include fixed WiMAX and any other fixed wireless technologies. It includes both residential subscriptions and subscriptions for organizations. | E2: World Telecommunication/ICT Indicators Database, International Telecommunication Union (ITU) | F2: Infrastructure: Communications | G2: WB_WDI | H2: number of subscriptions | I2: Annual | J2: 1998-2025 | K2: Sum | L2: Methodology: The data can be collected by asking all ISPs in the country to provide the number of their fixed -broadband subscriptions (by type � cable, DSL, optical fiber, other, satellite, and terrestrial fixed wireless broadband). Statistical concept(s): The data can be collected by asking all ISPs in the country to provide the number of their fixed -broadband subscriptions (by type � cable, DSL, optical fiber, other, satellite, and terrestrial fixed wireless broadband). | O2: Please cite the International Telecommunication Union for third-party use of these data. | P2: https://datacatalog.worldbank.org/int/public-licenses#cc-by
A3: IT.NET.BBND.P2 | B3: CC BY-4.0 | C3: Fixed broadband subscriptions (per 100 people) | D3: Fixed broadband subscriptions refers to fixed subscriptions to high-speed access to the public Internet (a TCP/IP connection), at downstream speeds equal to, or greater than, 256 kbit/s. This includes cable modem, DSL, fiber-to-the-home/building, other fixed (wired)-broadband subscriptions, satellite broadband and terrestrial fixed wireless broadband. This total is measured irrespective of the method of payment. It excludes subscriptions that have access to data communications (including the Internet) via mobile-cellular networks. It should include fixed WiMAX and any other fixed wireless technologies. It includes both residential subscriptions and subscriptions for organizations. | E3: World Telecommunication/ICT Indicators Database, International Telecommunication Union (ITU) | F3: Infrastructure: Communications | G3: WB_WDI | H3: number of subscriptions*100/population | I3: Annual | J3: 1998-2025 | K3: Weighted average | L3: Methodology: Data refer to subscriptions to high-speed access to the public Internet (a TCP/IP connection), at downstream speeds equal to, or greater than, 256 kbit/s. This includes cable modem, DSL, fibre-to-the-home/building and other fixed (wired)-broadband subscriptions. This total is measured irrespective of the method of payment. It excludes subscriptions that have access to data communications (including the Internet) via mobile-cellular networks. It excludes technologies listed under the wireless-broadband category. Fixed broadband Internet subscribers per 100 people is obtained by dividing the number of fixed broadband Internet subscribers by the population and then multiplying by 100. For additional/latest information on sources and country notes, please also refer to: https://www.itu.int/en/ITU-D/Statistics/Pages/stat/default.aspx Statistical concept(s): The data can be collected by asking all ISPs in the country to provide the number of their fixed -broadband subscriptions (by type � cable, DSL, optical fiber, other, satellite, and terrestrial fixed wireless broadband). This indicator can be divided by the population and multiplied by 100 to obtain fixed-broadband subscriptions per 100 people. | M3: The quality of an economy's infrastructure, including power and communications, is an important element in investment decisions for both domestic and foreign investors. Government effort alone is not enough to meet the need for investments in modern infrastructure; public-private partnerships, especially those involving local providers and financiers, are critical for lowering costs and delivering value for money. In telecommunications, competition in the marketplace, along with sound regulation, is lowering costs, improving quality, and easing access to services around the globe. Comparable statistics on access, use, quality, and affordability of ICT are needed to formulate growth-enabling policies for the sector and to monitor and evaluate the sector's impact on development. Although basic access data are available for many countries, in most developing countries little is known about who uses ICT; what they are used for (school, work, business, research, government); and how they affect people and businesses. The global Partnership on Measuring ICT for Development is helping to set standards, harmonize information and communications technology statistics, and build statistical capacity in developing countries. However, despite significant improvements in the developing world, the gap between the ICT haves and have-nots remains. There are several economic gains associated with broadband. For example, with DSL, users can use a single standard phone line for both voice and data services. This enables them to surf the Internet and call a friend at the same time - all using the same phone line. Broadband also enhances many Internet applications such as new e-government services like electronic tax filing, online health care services, e-learning and increased levels of electronic commerce. Access to telecommunication services rose on an unprecedented scale over the past two decades. This growth was driven primarily by wireless technologies and liberalization of telecommunications markets, which have enabled faster and less costly network rollout. Mobile communications have a particularly important impact in rural areas. The mobility, ease of use, flexible deployment, and relatively low and declining rollout costs of wireless technologies enable them to reach rural populations with low levels of income and literacy. The next billion mobile subscribers will consist mainly of the rural poor. Access is the key to delivering telecommunications services to people. If the service is not affordable to most people, goals of universal usage will not be met. Over the past decade new financing and technology, along with privatization and market liberalization, have spurred dramatic growth in telecommunications in many countries. With the rapid development of mobile telephony and the global expansion of the Internet, information and communication technologies are increasingly recognized as essential tools of development, contributing to global integration and enhancing public sector effectiveness, efficiency, and transparency. | N3: Data are collected by national statistics offices through household surveys. Because survey questions and definitions differ, the estimates may not be strictly comparable across countries. Fixed broadband Internet includes cable modem, DSL, fibre and other fixed broadband technology (such as satellite broadband Internet, Ethernet LANs, fixed-wireless access, Wireless Local Area Network, WiMAX etc.). Subscribers with access to data communications (including the Internet) via mobile cellular networks are excluded. Advertised and real speeds can differ substantially. In some countries, regulatory authorities monitor the speed and quality of broadband services and oblige operators to provide accurate quality-of-service information to end users. Regional and global totals are calculated as unweighted sums of the country values. Regional and global penetration rates (per 100 inhabitants) are weighted averages of the country values weighted by the population of the countries/regions. Discrepancies between global and national figures may arise when countries use a different definition than the one used by ITU. Discrepancies may also arise in cases where the end of a fiscal year differs from that used by ITU, which is end of December of every year. A number of countries have fiscal years that end in March or June of every year. | O3: Please cite the International Telecommunication Union for third-party use of these data. | P3: https://datacatalog.worldbank.org/int/public-licenses#cc-by
A4: IT.MLT.MAIN | B4: CC BY-4.0 | C4: Fixed telephone subscriptions | D4: Fixed telephone subscriptions refers to the sum of active number of analogue fixed telephone lines, voice-over-IP (VoIP) subscriptions, fixed wireless local loop (WLL) subscriptions, ISDN voice-channel equivalents and fixed public payphones. | E4: World Telecommunication/ICT Indicators Database, International Telecommunication Union (ITU) | F4: Infrastructure: Communications | G4: WB_WDI | H4: number of subscriptions | I4: Annual | J4: 1960-2025 | K4: Sum | L4: Methodology: A fixed telephone line (previously called main telephone line in operation) is an active line connecting the subscriber's terminal equipment to the public switched telephone network (PSTN) and which has a dedicated port in the telephone exchange equipment. This term is synonymous with the terms main station or Direct Exchange Line (DEL) that are commonly used in telecommunication documents. It may not be the same as an access line or a subscriber. This should include the active number of analog fixed telephone lines, ISDN channels, fixed wireless, public payphones and VoIP subscriptions. Active lines are those that have registered an activity in the past three months. Data on fixed telephone lines are derived using administrative data that countries (usually the regulatory telecommunication authority or the Ministry in charge of telecommunications) regularly, and at least annually, collect from telecommunications operators. Data are considered to be very reliable, timely, and complete. Data for this indicator are readily available for approximately 90 percent of countries, either through ITU's World Telecommunication Indicators questionnaires or from official information available on the Ministry or Regulator's website. For the rest, information can be aggregated through operators' data (mainly through annual reports) and complemented by market research reports. For additional/latest information on sources and country notes, please also refer to: https://www.itu.int/en/ITU-D/Statistics/Pages/stat/default.aspx Statistical concept(s): Data can be collected and aggregated at the country level by asking all licensed fixed-telephone line operators how many fixed-telephone subscriptions they have. | M4: The quality of an economy's infrastructure, including power and communications, is an important element in investment decisions for both domestic and foreign investors. Government effort alone is not enough to meet the need for investments in modern infrastructure; public-private partnerships, especially those involving local providers and financiers, are critical for lowering costs and delivering value for money. In telecommunications, competition in the marketplace, along with sound regulation, is lowering costs, improving quality, and easing access to services around the globe. Access to telecommunication services rose on an unprecedented scale over the past two decades. This growth was driven primarily by wireless technologies and liberalization of telecommunications markets, which have enabled faster and less costly network rollout. Fixed telephone lines are those that connect a subscriber's terminal equipment to the public switched telephone network and that have a port on a telephone exchange. This term is synonymous with the term main station or Direct Exchange Line (DEL) that is commonly used in telecommunication documents. Integrated services digital network channels and fixed wireless subscribers are included. A fixed line also refers to a phone which uses a solid medium telephone line such as a metal wire or fiber optic cable for transmission as distinguished from a mobile cellular line which uses radio waves for transmission. Over the past decade new financing and technology, along with privatization and market liberalization, have spurred dramatic growth in telecommunications in many countries. With the rapid development of mobile telephony and the global expansion of the Internet, information and communication technologies are increasingly recognized as essential tools of development, contributing to global integration and enhancing public sector effectiveness, efficiency, and transparency. | N4: Operators have traditionally been the main source of telecommunications data, so information on subscriptions has been widely available for most countries. This gives a general idea of access, but a more precise measure is the penetration rate - the share of households with access to telecommunications. During the past few years more information on information and communication technology use has become available from household and business surveys. Also important are data on actual use of telecommunications services. Ideally, statistics on telecommunications (and other information and communications technologies) should be compiled for all three measures: subscriptions, access, and use. The quality of data varies among reporting countries as a result of differences in regulations covering data provision and availability. Discrepancies between global and national figures may arise when countries use a different definition than the one used by ITU. For example, some countries do not include the number of ISDN channels when calculating the number of fixed telephone lines. Discrepancies may also arise in cases where the end of a fiscal year differs from that used by ITU, which is the end of December of every year. A number of countries have fiscal years that end in March or June of every year. Data are usually not adjusted but discrepancies in the definition, reference year or the break in comparability in between years are noted in a data note. For this reason, data are not always strictly comparable. Missing values are estimated by ITU. | O4: Please cite the International Telecommunication Union for third-party use of these data. | P4: https://datacatalog.worldbank.org/int/public-licenses#cc-by
A5: IT.MLT.MAIN.P2 | B5: CC BY-4.0 | C5: Fixed telephone subscriptions (per 100 people) | D5: Fixed telephone subscriptions refers to the sum of active number of analogue fixed telephone lines, voice-over-IP (VoIP) subscriptions, fixed wireless local loop (WLL) subscriptions, ISDN voice-channel equivalents and fixed public payphones. | E5: World Telecommunication/ICT Indicators Database, International Telecommunication Union (ITU) | F5: Infrastructure: Communications | G5: WB_WDI | H5: number of subscriptions*100/population | I5: Annual | J5: 1960-2025 | K5: Weighted average | L5: Methodology: A fixed telephone line (previously called main telephone line in operation) is an active line connecting the subscriber's terminal equipment to the public switched telephone network (PSTN) and which has a dedicated port in the telephone exchange equipment. This term is synonymous with the terms main station or Direct Exchange Line (DEL) that are commonly used in telecommunication documents. It may not be the same as an access line or a subscriber. This should include the active number of analog fixed telephone lines, ISDN channels, fixed wireless, public payphones and VoIP subscriptions. Active lines are those that have registered an activity in the past three months. Data on fixed telephone lines are derived using administrative data that countries (usually the regulatory telecommunication authority or the Ministry in charge of telecommunications) regularly, and at least annually, collect from telecommunications operators. Data are considered to be very reliable, timely, and complete. Data for this indicator are readily available for approximately 90 percent of countries, either through ITU's World Telecommunication Indicators questionnaires or from official information available on the Ministry or Regulator's website. For the rest, information can be aggregated through operators' data (mainly through annual reports) and complemented by market research reports. Telephone lines (per 100 people) indicator is derived by all telephone lines divided by the country's population and multiplied by 100. For additional/latest information on sources and country notes, please also refer to: https://www.itu.int/en/ITU-D/Statistics/Pages/stat/default.aspx Statistical concept(s): Data can be collected and aggregated at the country level by asking all licensed fixed-telephone line operators how many fixed-telephone subscriptions they have. This indicator can be divided by the population and multiplied by 100 to obtain fixed telephone subscriptions per 100 people. | M5: The quality of an economy's infrastructure, including power and communications, is an important element in investment decisions for both domestic and foreign investors. Government effort alone is not enough to meet the need for investments in modern infrastructure; public-private partnerships, especially those involving local providers and financiers, are critical for lowering costs and delivering value for money. In telecommunications, competition in the marketplace, along with sound regulation, is lowering costs, improving quality, and easing access to services around the globe. Access to telecommunication services rose on an unprecedented scale over the past two decades. This growth was driven primarily by wireless technologies and liberalization of telecommunications markets, which have enabled faster and less costly network rollout. Fixed telephone lines are those that connect a subscriber's terminal equipment to the public switched telephone network and that have a port on a telephone exchange. This term is synonymous with the term main station or Direct Exchange Line (DEL) that is commonly used in telecommunication documents. Integrated services digital network channels and fixed wireless subscribers are included. A fixed line also refers to a phone which uses a solid medium telephone line such as a metal wire or fiber optic cable for transmission as distinguished from a mobile cellular line which uses radio waves for transmission. Over the past decade new financing and technology, along with privatization and market liberalization, have spurred dramatic growth in telecommunications in many countries. With the rapid development of mobile telephony and the global expansion of the Internet, information and communication technologies are increasingly recognized as essential tools of development, contributing to global integration and enhancing public sector effectiveness, efficiency, and transparency. | N5: Operators have traditionally been the main source of telecommunications data, so information on subscriptions has been widely available for most countries. This gives a general idea of access, but a more precise measure is the penetration rate - the share of households with access to telecommunications. During the past few years more information on information and communication technology use has become available from household and business surveys. Also important are data on actual use of telecommunications services. Ideally, statistics on telecommunications (and other information and communications technologies) should be compiled for all three measures: subscriptions, access, and use. The quality of data varies among reporting countries as a result of differences in regulations covering data provision and availability. Discrepancies between global and national figures may arise when countries use a different definition than the one used by ITU. For example, some countries do not include the number of ISDN channels when calculating the number of fixed telephone lines. Discrepancies may also arise in cases where the end of a fiscal year differs from that used by ITU, which is the end of December of every year. A number of countries have fiscal years that end in March or June of every year. Data are usually not adjusted but discrepancies in the definition, reference year or the break in comparability in between years are noted in a data note. For this reason, data are not always strictly comparable. Missing values are estimated by ITU. | O5: Please cite the International Telecommunication Union for third-party use of these data. | P5: https://datacatalog.worldbank.org/int/public-licenses#cc-by
A6: TX.VAL.ICTG.ZS.UN | B6: CC BY-4.0 | C6: ICT goods exports (% of total goods exports) | D6: Information and communication technology goods exports include computers and peripheral equipment, communication equipment, consumer electronic equipment, electronic components, and other information and technology goods (miscellaneous). | E6: UNCTADstat database, UN Conference on Trade and Development (UNCTAD), uri: http://unctadstat.unctad.org/ReportFolders/reportFolders.aspx | F6: Infrastructure: Communications | G6: WB_WDI | I6: Annual | J6: 2000-2024 | K6: Weighted average | L6: Methodology: Information and communication technology goods exports include computers and peripheral equipment, communication equipment, consumer electronic equipment, electronic components, and other information and technology goods (miscellaneous). Software is generally excluded, as there is a preference to record it under services (not an ICT good but an ICT product) to the extent possible. However it is hard to completely exclude embedded software from certain types of ICT goods, such as video game consoles (see for example the discussion on page 30 of the OECD guide cited below). ICT goods exports as a percentage of total goods exports is calculated for each country by dividing the value of its ICT goods exports by the total value of its goods exports. The result is then multiplied by 100 to be expressed as a percentage. ICT goods are defined according to the OECD�s Guide on Measuring the Information Society 2011 for Harmonized System (HS) 2007 and adapted to HS12 by UNCTAD in collaboration with UNSD (United Nations Statistics Division). This new list consists of 93 goods defined at the 6 digit level of the 2012 version of the HS. The technical note is available online at: http://unctad.org/en/PublicationsLibrary/tn_unctad_ict4d02_en.pdf Data were downloaded from COMTRADE according to the reported classification (HS92, 96, 02, 07, 12) and aggregated into ICT groups by UNCTAD. | M6: The digital and information revolution has changed the way the world learns, communicates, does business, and treats illnesses. New information and communications technologies (ICT) offer vast opportunities for progress in all walks of life in all countries - opportunities for economic growth, improved health, better service delivery, learning through distance education, and social and cultural advances. Comparable statistics on access, use, quality, and affordability of ICT are needed to formulate growth-enabling policies for the sector and to monitor and evaluate the sector's impact on development. Although basic access data are available for many countries, in most developing countries little is known about who uses ICT; what they are used for (school, work, business, research, government); and how they affect people and businesses. The global Partnership on Measuring ICT for Development is helping to set standards, harmonize information and communications technology statistics, and build statistical capacity in developing countries. For more information see www.itu.int/ITU-D/ict/partnership/. The work of the Partnership is directed towards achieving internationally comparable and reliable ICT statistics. In order to achieve this, its members are involved in developing and maintaining a core list of ICT indicators. Other activities include the compilation and dissemination of ICT data, and the provision of technical assistance enabling statistical agencies to collect data that underlie the core list of ICT indicators. | N6: Detailed trade data are widely available from country trade statistics. These are collected by the UNSD and published in their UN COMTRADE database. The ICT goods trade indicators are usually compiled by interested international and national agencies using COMTRADE data. Concepts are therefore consistent with those applying to the COMTRADE database. The main statistical issue associated with this indicator appears to be the different treatment of re-exports and re-imports by countries, depending on whether the Special or General Trade System is used.2 Re-imports are separately reported for some countries and the value of ICT re-imports (which is included in the value of ICT imports for those countries) is generally small. | P6: https://datacatalog.worldbank.org/int/public-licenses#cc-by
A7: TM.VAL.ICTG.ZS.UN | B7: CC BY-4.0 | C7: ICT goods imports (% total goods imports) | D7: Information and communication technology goods imports include computers and peripheral equipment, communication equipment, consumer electronic equipment, electronic components, and other information and technology goods (miscellaneous). | E7: UNCTADstat database, UN Conference on Trade and Development (UNCTAD), uri: http://unctadstat.unctad.org/ReportFolders/reportFolders.aspx | F7: Infrastructure: Communications | G7: WB_WDI | I7: Annual | J7: 2000-2024 | K7: Weighted average | L7: Methodology: Information and communication technology goods imports include computers and peripheral equipment, communication equipment, consumer electronic equipment, electronic components, and other information and technology goods (miscellaneous). Software is generally excluded, as there is a preference to record it under services (not an ICT good but an ICT product) to the extent possible. However it is hard to completely exclude embedded software from certain types of ICT goods, such as video game consoles (see for example the discussion on page 30 of the OECD guide cited below). ICT goods imports as a percentage of total imports is calculated for each country by dividing the value of its ICT goods imports by the total value of its goods imports. The result is then multiplied by 100 to be expressed as a percentage. ICT goods are defined according to the OECD�s Guide on Measuring the Information Society 2011 for Harmonized System (HS) 2007 and adapted to HS12 by UNCTAD in collaboration with UNSD (United Nations Statistics Division). This new list consists of 93 goods defined at the 6 digit level of the 2012 version of the HS. The technical note is available online at: http://unctad.org/en/PublicationsLibrary/tn_unctad_ict4d02_en.pdf Data were downloaded from COMTRADE according to the reported classification (HS92, 96, 02, 07, 12) and aggregated into ICT groups by UNCTAD. | M7: The digital and information revolution has changed the way the world learns, communicates, does business, and treats illnesses. New information and communications technologies (ICT) offer vast opportunities for progress in all walks of life in all countries - opportunities for economic growth, improved health, better service delivery, learning through distance education, and social and cultural advances. Comparable statistics on access, use, quality, and affordability of ICT are needed to formulate growth-enabling policies for the sector and to monitor and evaluate the sector's impact on development. Although basic access data are available for many countries, in most developing countries little is known about who uses ICT; what they are used for (school, work, business, research, government); and how they affect people and businesses. The global Partnership on Measuring ICT for Development is helping to set standards, harmonize information and communications technology statistics, and build statistical capacity in developing countries. For more information see www.itu.int/ITU-D/ict/partnership/. The work of the Partnership is directed towards achieving internationally comparable and reliable ICT statistics. In order to achieve this, its members are involved in developing and maintaining a core list of ICT indicators. Other activities include the compilation and dissemination of ICT data, and the provision of technical assistance enabling statistical agencies to collect data that underlie the core list of ICT indicators. | N7: Detailed trade data are widely available from country trade statistics. These are collected by the UNSD and published in their UN COMTRADE database. The ICT goods trade indicators are usually compiled by interested international and national agencies using COMTRADE data. Concepts are therefore consistent with those applying to the COMTRADE database. The main statistical issue associated with this indicator appears to be the different treatment of re-exports and re-imports by countries, depending on whether the Special or General Trade System is used.2 Re-imports are separately reported for some countries and the value of ICT re-imports (which is included in the value of ICT imports for those countries) is generally small. | P7: https://datacatalog.worldbank.org/int/public-licenses#cc-by
A8: BX.GSR.CCIS.ZS | B8: CC BY-4.0 | C8: ICT service exports (% of service exports, BoP) | D8: Information and communication technology service exports include computer and communications services (telecommunications and postal and courier services) and information services (computer data and news-related service transactions). | E8: Balance of Payments Statistics Yearbook and data files, International Monetary Fund (IMF) | F8: Infrastructure: Communications | G8: WB_WDI | I8: Annual | J8: 1960-2025 | K8: Weighted average | L8: Methodology: The balance of payments (BoP) is a double-entry accounting system that shows all flows of goods and services into and out of an economy; all transfers that are the counterpart of real resources or financial claims provided to or by the rest of the world without a quid pro quo, such as donations and grants; and all changes in residents' claims on and liabilities to nonresidents that arise from economic transactions. All transactions are recorded twice - once as a credit and once as a debit. In principle the net balance should be zero, but in practice the accounts often do not balance, requiring inclusion of a balancing item, net errors and omissions. The concepts and definitions underlying the data are based on the sixth edition of the International Monetary Fund's (IMF) Balance of Payments Manual. | M8: The balance of payments records an economy's transactions with the rest of the world. Balance of payments accounts are divided into two groups: the current account, which records transactions in goods, services, income, and current transfers, and the capital and financial account, which records capital transfers, acquisition or disposal of non-produced, nonfinancial assets, and transactions in financial assets and liabilities. | N8: Discrepancies may arise in the balance of payments because there is no single source for balance of payments data and therefore no way to ensure that the data are fully consistent. Sources include customs data, monetary accounts of the banking system, external debt records, information provided by enterprises, surveys to estimate service transactions, and foreign exchange records. Differences in collection methods - such as in timing, definitions of residence and ownership, and the exchange rate used to value transactions - contribute to net errors and omissions. In addition, smuggling and other illegal or quasi-legal transactions may be unrecorded or misrecorded. | O8: Note: Data are based on the sixth edition of the IMF's Balance of Payments Manual (BPM6) and are only available from 2005 onwards. | P8: https://datacatalog.worldbank.org/int/public-licenses#cc-by
A9: BX.GSR.CCIS.CD | B9: CC BY-4.0 | C9: ICT service exports (BoP, current US$) | D9: Information and communication technology service exports include computer and communications services (telecommunications and postal and courier services) and information services (computer data and news-related service transactions). Data are in current U.S. dollars. | E9: Balance of Payments Statistics Yearbook and data files, International Monetary Fund (IMF) | F9: Infrastructure: Communications | G9: WB_WDI | I9: Annual | J9: 1960-2025 | K9: Sum | L9: Methodology: The balance of payments (BoP) is a double-entry accounting system that shows all flows of goods and services into and out of an economy; all transfers that are the counterpart of real resources or financial claims provided to or by the rest of the world without a quid pro quo, such as donations and grants; and all changes in residents' claims on and liabilities to nonresidents that arise from economic transactions. All transactions are recorded twice - once as a credit and once as a debit. In principle the net balance should be zero, but in practice the accounts often do not balance, requiring inclusion of a balancing item, net errors and omissions. The concepts and definitions underlying the data are based on the sixth edition of the International Monetary Fund's (IMF) Balance of Payments Manual. | O9: Note: Data are based on the sixth edition of the IMF's Balance of Payments Manual (BPM6) and are only available from 2005 onwards. | P9: https://datacatalog.worldbank.org/int/public-licenses#cc-by
A10: IT.NET.USER.ZS | B10: CC BY-4.0 | C10: Individuals using the Internet (% of population) | D10: Internet users are individuals who have used the Internet (from any location) in the last 3 months. The Internet can be used via a computer, mobile phone, personal digital assistant, games machine, digital TV etc. | E10: World Telecommunication/ICT Indicators Database, International Telecommunication Union (ITU), uri: https://datahub.itu.int/ | F10: Infrastructure: Communications | G10: WB_WDI | H10: % of population | I10: Annual | J10: 1990-2025 | K10: Weighted average | L10: Methodology: The Internet is a world-wide public computer network. It provides access to a number of communication services including the World Wide Web and carries email, news, entertainment and data files, irrespective of the device used (not assumed to be only via a computer - it may also be by mobile phone, PDA, games machine, digital TV etc.). Access can be via a fixed or mobile network. For additional/latest information on sources and country notes, please also refer to: https://www.itu.int/en/ITU-D/Statistics/Pages/stat/default.aspx Statistical concept(s): The number of in-scope individuals using the Internet is calculated by aggregating the weighted responses. The proportion of individuals using the Internet is expressed as a percentage and is calculated by dividing the total number of in-scope individuals using the Internet by the total number of in-scope individuals, and then multiplying the result by 100. | M10: The digital and information revolution has changed the way the world learns, communicates, does business, and treats illnesses. New information and communications technologies (ICT) offer vast opportunities for progress in all walks of life in all countries - opportunities for economic growth, improved health, better service delivery, learning through distance education, and social and cultural advances. Today's smartphones and tablets have computer power equivalent to that of yesterday's computers and provide a similar range of functions. Device convergence is thus rendering the conventional definition obsolete. Comparable statistics on access, use, quality, and affordability of ICT are needed to formulate growth-enabling policies for the sector and to monitor and evaluate the sector's impact on development. Although basic access data are available for many countries, in most developing countries little is known about who uses ICT; what they are used for (school, work, business, research, government); and how they affect people and businesses. The global Partnership on Measuring ICT for Development is helping to set standards, harmonize information and communications technology statistics, and build statistical capacity in developing countries. However, despite significant improvements in the developing world, the gap between the ICT haves and have-nots remains. | N10: Operators have traditionally been the main source of telecommunications data, so information on subscriptions has been widely available for most countries. This gives a general idea of access, but a more precise measure is the penetration rate - the share of households with access to telecommunications. During the past few years more information on information and communication technology use has become available from household and business surveys. Also important are data on actual use of telecommunications services. Ideally, statistics on telecommunications (and other information and communications technologies) should be compiled for all three measures: subscriptions, access, and use. The quality of data varies among reporting countries as a result of differences in regulations covering data provision and availability. Discrepancies may also arise in cases where the end of a fiscal year differs from that used by ITU, which is the end of December of every year. A number of countries have fiscal years that end in March or June of every year. | O10: Please cite the International Telecommunication Union for third-party use of these data. | P10: https://datacatalog.worldbank.org/int/public-licenses#cc-by
A11: IT.NET.USER.FE.ZS | B11: CC BY-4.0 | C11: Individuals using the Internet, female (% of female population) | D11: This indicator refers to female individuals who have used the Internet (from any location) in the last 3 months. The Internet can be used via a computer, mobile phone, personal digital assistant, games machine, digital TV etc. | E11: World Telecommunication/ICT Indicators Database, International Telecommunication Union (ITU) | F11: Infrastructure: Communications | G11: WB_WDI | H11: Percent | I11: Annual | J11: 2000-2025 | K11: Weighted average | L11: Methodology: The Internet is a world-wide public computer network. It provides access to a number of communication services including the World Wide Web and carries email, news, entertainment and data files, irrespective of the device used (not assumed to be only via a computer - it may also be by mobile phone, PDA, games machine, digital TV etc.). Access can be via a fixed or mobile network. For additional/latest information on sources and country notes, please also refer to: https://www.itu.int/en/ITU-D/Statistics/Pages/stat/default.aspx | M11: The digital and information revolution has changed the way the world learns, communicates, does business, and treats illnesses. New information and communications technologies (ICT) offer vast opportunities for progress in all walks of life in all countries - opportunities for economic growth, improved health, better service delivery, learning through distance education, and social and cultural advances. Today's smartphones and tablets have computer power equivalent to that of yesterday's computers and provide a similar range of functions. Device convergence is thus rendering the conventional definition obsolete. Comparable statistics on access, use, quality, and affordability of ICT are needed to formulate growth-enabling policies for the sector and to monitor and evaluate the sector's impact on development. Although basic access data are available for many countries, in most developing countries little is known about who uses ICT; what they are used for (school, work, business, research, government); and how they affect people and businesses. The global Partnership on Measuring ICT for Development is helping to set standards, harmonize information and communications technology statistics, and build statistical capacity in developing countries. However, despite significant improvements in the developing world, the gap between the ICT haves and have-nots remains. | N11: Operators have traditionally been the main source of telecommunications data, so information on subscriptions has been widely available for most countries. This gives a general idea of access, but a more precise measure is the penetration rate - the share of households with access to telecommunications. During the past few years more information on information and communication technology use has become available from household and business surveys. Also important are data on actual use of telecommunications services. Ideally, statistics on telecommunications (and other information and communications technologies) should be compiled for all three measures: subscriptions, access, and use. The quality of data varies among reporting countries as a result of differences in regulations covering data provision and availability. Discrepancies may also arise in cases where the end of a fiscal year differs from that used by ITU, which is the end of December of every year. A number of countries have fiscal years that end in March or June of every year. | O11: Please cite the International Telecommunication Union for third-party use of these data. | P11: https://datacatalog.worldbank.org/int/public-licenses#cc-by
A12: IT.NET.USER.MA.ZS | B12: CC BY-4.0 | C12: Individuals using the Internet, male (% of male population) | D12: This indicator refers to male individuals who have used the Internet (from any location) in the last 3 months. The Internet can be used via a computer, mobile phone, personal digital assistant, games machine, digital TV etc. | E12: World Telecommunication/ICT Indicators Database, International Telecommunication Union (ITU) | F12: Infrastructure: Communications | G12: WB_WDI | H12: Percent | I12: Annual | J12: 2000-2025 | K12: Weighted average | L12: Methodology: The Internet is a world-wide public computer network. It provides access to a number of communication services including the World Wide Web and carries email, news, entertainment and data files, irrespective of the device used (not assumed to be only via a computer - it may also be by mobile phone, PDA, games machine, digital TV etc.). Access can be via a fixed or mobile network. For additional/latest information on sources and country notes, please also refer to: https://www.itu.int/en/ITU-D/Statistics/Pages/stat/default.aspx | M12: The digital and information revolution has changed the way the world learns, communicates, does business, and treats illnesses. New information and communications technologies (ICT) offer vast opportunities for progress in all walks of life in all countries - opportunities for economic growth, improved health, better service delivery, learning through distance education, and social and cultural advances. Today's smartphones and tablets have computer power equivalent to that of yesterday's computers and provide a similar range of functions. Device convergence is thus rendering the conventional definition obsolete. Comparable statistics on access, use, quality, and affordability of ICT are needed to formulate growth-enabling policies for the sector and to monitor and evaluate the sector's impact on development. Although basic access data are available for many countries, in most developing countries little is known about who uses ICT; what they are used for (school, work, business, research, government); and how they affect people and businesses. The global Partnership on Measuring ICT for Development is helping to set standards, harmonize information and communications technology statistics, and build statistical capacity in developing countries. However, despite significant improvements in the developing world, the gap between the ICT haves and have-nots remains. | N12: Operators have traditionally been the main source of telecommunications data, so information on subscriptions has been widely available for most countries. This gives a general idea of access, but a more precise measure is the penetration rate - the share of households with access to telecommunications. During the past few years more information on information and communication technology use has become available from household and business surveys. Also important are data on actual use of telecommunications services. Ideally, statistics on telecommunications (and other information and communications technologies) should be compiled for all three measures: subscriptions, access, and use. The quality of data varies among reporting countries as a result of differences in regulations covering data provision and availability. Discrepancies may also arise in cases where the end of a fiscal year differs from that used by ITU, which is the end of December of every year. A number of countries have fiscal years that end in March or June of every year. | O12: Please cite the International Telecommunication Union for third-party use of these data. | P12: https://datacatalog.worldbank.org/int/public-licenses#cc-by
A13: IT.CEL.SETS | B13: CC BY-4.0 | C13: Mobile cellular subscriptions | D13: Mobile cellular telephone subscriptions are subscriptions to a public mobile telephone service that provide access to the PSTN using cellular technology. The indicator includes (and is split into) the number of postpaid subscriptions, and the number of active prepaid accounts (i.e. that have been used during the last three months). The indicator applies to all mobile cellular subscriptions that offer voice communications. It excludes subscriptions via data cards or USB modems, subscriptions to public mobile data services, private trunked mobile radio, telepoint, radio paging and telemetry services. | E13: World Telecommunication/ICT Indicators Database, International Telecommunication Union (ITU) | F13: Infrastructure: Communications | G13: WB_WDI | H13: number of subscriptions | I13: Annual | J13: 1960-2025 | K13: Sum | L13: Methodology: Refers to the subscriptions to a public mobile telephone service and provides access to Public Switched Telephone Network (PSTN) using cellular technology, including number of pre-paid SIM cards active during the past three months. This includes both analogue and digital cellular systems (IMT-2000 (Third Generation, 3G) and 4G subscriptions, but excludes mobile broadband subscriptions via data cards or USB modems. Subscriptions to public mobile data services, private trunked mobile radio, telepoint or radio paging, and telemetry services should also be excluded. This should include all mobile cellular subscriptions that offer voice communications. Data on mobile cellular subscribers are derived using administrative data that countries (usually the regulatory telecommunication authority or the Ministry in charge of telecommunications) regularly, and at least annually, collect from telecommunications operators. Data for this indicator are readily available for approximately 90 percent of countries, either through ITU's World Telecommunication Indicators questionnaires or from official information available on the Ministry or Regulator's website. For the rest, information can be aggregated through operators' data (mainly through annual reports) and complemented by market research reports. For additional/latest information on sources and country notes, please also refer to: https://www.itu.int/en/ITU-D/Statistics/Pages/stat/default.aspx Statistical concept(s): Data can be collected from all licensed mobile-cellular operators in the country, and then aggregated at the country level. If retail mobile-cellular services are also provided by nonfacilities-based operators (i.e., mobile virtual network operators), care should be taken to avoid double counting. One difficulty that may arise is that operators may have different definitions of �active� and therefore may not be able to provide the data according to the recommended definition (i.e., used in the last three months). | M13: The quality of an economy's infrastructure, including power and communications, is an important element in investment decisions for both domestic and foreign investors. Government effort alone is not enough to meet the need for investments in modern infrastructure; public-private partnerships, especially those involving local providers and financiers, are critical for lowering costs and delivering value for money. In telecommunications, competition in the marketplace, along with sound regulation, is lowering costs, improving quality, and easing access to services around the globe. Access to telecommunication services rose on an unprecedented scale over the past two decades. This growth was driven primarily by wireless technologies and liberalization of telecommunications markets, which have enabled faster and less costly network rollout. The International Telecommunication Union (ITU) estimates that there were about 6 billion mobile subscriptions globally in the early 2010s. No technology has ever spread faster around the world. Mobile communications have a particularly important impact in rural areas. The mobility, ease of use, flexible deployment, and relatively low and declining rollout costs of wireless technologies enable them to reach rural populations with low levels of income and literacy. The next billion mobile subscribers will consist mainly of the rural poor. Access is the key to delivering telecommunications services to people. If the service is not affordable to most people, goals of universal usage will not be met. Mobile cellular telephone subscriptions are subscriptions to a public mobile telephone service using cellular technology, which provide access to the public switched telephone network (PSTN) using cellular technology. It includes postpaid and prepaid subscriptions and includes analogue and digital cellular systems. Over the past decade new financing and technology, along with privatization and market liberalization, have spurred dramatic growth in telecommunications in many countries. With the rapid development of mobile telephony and the global expansion of the Internet, information and communication technologies are increasingly recognized as essential tools of development, contributing to global integration and enhancing public sector effectiveness, efficiency, and transparency. | N13: Operators have traditionally been the main source of telecommunications data, so information on subscriptions has been widely available for most countries. This gives a general idea of access, but a more precise measure is the penetration rate - the share of households with access to telecommunications. During the past few years more information on information and communication technology use has become available from household and business surveys. Also important are data on actual use of telecommunications services. Ideally, statistics on telecommunications (and other information and communications technologies) should be compiled for all three measures: subscriptions, access, and use. The quality of data varies among reporting countries as a result of differences in regulations covering data provision and availability. Discrepancies between global and national figures may arise when countries use a different definition than the one used by ITU. For example, some countries do not include the number of ISDN channels when calculating the number of fixed telephone lines. Discrepancies may also arise in cases where the end of a fiscal year differs from that used by ITU, which is the end of December of every year. A number of countries have fiscal years that end in March or June of every year. Data are usually not adjusted but discrepancies in the definition, reference year or the break in comparability in between years are noted in a data note. For this reason, data are not always strictly comparable. Missing values are estimated by ITU. Mobile subscriptions include both analogue and digital cellular systems (IMT-2000 (Third Generation, 3G) and 4G subscriptions, but excludes mobile broadband subscriptions via data cards or USB modems. Subscriptions to public mobile data services, private trunked mobile radio, telepoint or radio paging, and telemetry services are also excluded, but all mobile cellular subscriptions that offer voice communications are included. Both postpaid and prepaid subscriptions are included. | O13: Please cite the International Telecommunication Union for third-party use of these data. | P13: https://datacatalog.worldbank.org/int/public-licenses#cc-by
